Workbook

Sheet Projectbegroting
A1: * Als vorig projectnummer wordt ingevuld worden automatisch de gegevens gevuld vanuit vorig jaar. Wil je hier vanaf wijken, kijk dan in de dopdownlijst in kolom C, voor de keuze en Vul deze in bij Kolom B. | J1: jaar | K1: 46023
A2: Invulvelden | J2: Index | K2: 0
A5: Bedrijf | B5: BV | C5: Voorbeeldlijsten
A6: Vorig projectnummer | B6: 30626-0002
A7: Projectnaam vorig | B7: =_xlfn.XLOOKUP(B6,'report B_Project'!B:B,'report B_Project'!C:C,"niet bekend") -> Klant in beeld 2026
A8: Projectnaam nieuw | B8: Klant in zicht 2027
A9: Projectnummer nieuw | B9: 30626-0003
A10: Startdatum | B10: 46388
A11: Einddatum | B11: 46752
A13: Projectleider | B13: =_xlfn.XLOOKUP(B6,'report B_Project'!B:B,'report B_Project'!N:N,"niet bekend ") -> Pim de Burger | D13: persnummer | E13: =_xlfn.XLOOKUP(B13,Lijsten!N:N,Lijsten!O:O,"niet bekend") -> 25955
A14: Opdrachtgever | B14: =_xlfn.XLOOKUP(B6,'report B_Project'!B:B,'report B_Project'!P:P,"niet bekend ") -> Roel Bakker | D14: persnummer | E14: =_xlfn.XLOOKUP(B14,Lijsten!Q:Q,Lijsten!R:R,"niet bekend") -> niet bekend
A15: Controller | B15: =_xlfn.XLOOKUP(B6,'report B_Project'!B:B,'report B_Project'!R:R,"niet bekend ") -> George Pavel | D15: persnummer | E15: =_xlfn.XLOOKUP(B15,Lijsten!K:K,Lijsten!L:L,"niet bekend") -> 2061
A16: Handpoc / autopoc | B16: =_xlfn.XLOOKUP(B6,'report B_Project'!B:B,'report B_Project'!S:S,"niet bekend") -> AUT-POC
A18: Projectgroep | B18: Kosten
A19: Kostenplaats | B19: 7040
A20: kostendrager
A21: variant
A22: BTW-code | B22: NL-B
A24: Klantrekening | B24: 10021301
A25: Klantnaam | B25: Cito
A26: Projectcontract | B26: 2000000 | G26: jan | H26: feb | I26: maart | J26: april | K26: mei | L26: juni | M26: juli | N26: aug | O26: sept | P26: okt | Q26: nov | R26: dec | S26: check
F27: Standaardpatroon | G27: =1/12 -> 0.083333333 | H27: =1/12 -> 0.083333333 | I27: =1/12 -> 0.083333333 | J27: =1/12 -> 0.083333333 | K27: =1/12 -> 0.083333333 | L27: =1/12 -> 0.083333333 | M27: =1/12 -> 0.083333333 | N27: =1/12 -> 0.083333333 | ... R27: =1/12 -> 0.083333333 | S27: =SUM(G27:R27) -> 1
A28: Begroting | C28: Maandverdeling | G28: =G27 -> 0.083333333 | H28: =H27 -> 0.083333333 | I28: =I27 -> 0.083333333 | J28: =J27 -> 0.083333333 | K28: =K27 -> 0.083333333 | L28: =L27 -> 0.083333333 | M28: =M27 -> 0.083333333 | N28: =N27 -> 0.083333333 | ... R28: =R27 -> 0.083333333 | S28: =SUM(G28:R28) -> 1
A30: type | B30: code | C30: omschrijving | D30: tarief | E30: Begroting totaal | F30: aantal | G30: jan | H30: feb | I30: maart | J30: april | K30: mei | L30: juni | M30: juli | N30: aug | O30: sept | P30: okt | Q30: nov | R30: dec | S30: check
A31: Eigen medewerkers | B31: AM | C31: Accountmanager | D31: =_xlfn.XLOOKUP(B31,'report B_CategorieBoekjaar'!H:H,'report B_CategorieBoekjaar'!F:F,0) -> 81 | E31: =F31*D31 -> 0 | G31: =$E31*G$28 -> 0 | H31: =$E31*H$28 -> 0 | I31: =$E31*I$28 -> 0 | J31: =$E31*J$28 -> 0 | K31: =$E31*K$28 -> 0 | L31: =$E31*L$28 -> 0 | M31: =$E31*M$28 -> 0 | N31: =$E31*N$28 -> 0 | ... R31: =$E31*R$28 -> 0 | S31: =E31-SUM(G31:R31) -> 0
A32: Eigen medewerkers | B32: BU | C32: Bureauredacteur/documentalist | D32: =_xlfn.XLOOKUP(B32,'report B_CategorieBoekjaar'!H:H,'report B_CategorieBoekjaar'!F:F,0) -> 64 | E32: =F32*D32 -> 0 | G32: =$E32*G$28 -> 0 | H32: =$E32*H$28 -> 0 | I32: =$E32*I$28 -> 0 | J32: =$E32*J$28 -> 0 | K32: =$E32*K$28 -> 0 | L32: =$E32*L$28 -> 0 | M32: =$E32*M$28 -> 0 | N32: =$E32*N$28 -> 0 | ... R32: =$E32*R$28 -> 0 | S32: =E32-SUM(G32:R32) -> 0
A33: Eigen medewerkers | B33: CM | C33: Campagne Marketeer | D33: =_xlfn.XLOOKUP(B33,'report B_CategorieBoekjaar'!H:H,'report B_CategorieBoekjaar'!F:F,0) -> 80 | E33: =F33*D33 -> 0 | G33: =$E33*G$28 -> 0 | H33: =$E33*H$28 -> 0 | I33: =$E33*I$28 -> 0 | J33: =$E33*J$28 -> 0 | K33: =$E33*K$28 -> 0 | L33: =$E33*L$28 -> 0 | M33: =$E33*M$28 -> 0 | N33: =$E33*N$28 -> 0 | ... R33: =$E33*R$28 -> 0 | S33: =E33-SUM(G33:R33) -> 0
A34: Eigen medewerkers | B34: CS | C34: Content Specialist | D34: =_xlfn.XLOOKUP(B34,'report B_CategorieBoekjaar'!H:H,'report B_CategorieBoekjaar'!F:F,0) -> 64 | E34: =F34*D34 -> 0 | G34: =$E34*G$28 -> 0 | H34: =$E34*H$28 -> 0 | I34: =$E34*I$28 -> 0 | J34: =$E34*J$28 -> 0 | K34: =$E34*K$28 -> 0 | L34: =$E34*L$28 -> 0 | M34: =$E34*M$28 -> 0 | N34: =$E34*N$28 -> 0 | ... R34: =$E34*R$28 -> 0 | S34: =E34-SUM(G34:R34) -> 0
A35: Eigen medewerkers | B35: DES | C35: Toetsdeskundige | D35: =_xlfn.XLOOKUP(B35,'report B_CategorieBoekjaar'!H:H,'report B_CategorieBoekjaar'!F:F,0) -> 77 | E35: =F35*D35 -> 0 | G35: =$E35*G$28 -> 0 | H35: =$E35*H$28 -> 0 | I35: =$E35*I$28 -> 0 | J35: =$E35*J$28 -> 0 | K35: =$E35*K$28 -> 0 | L35: =$E35*L$28 -> 0 | M35: =$E35*M$28 -> 0 | N35: =$E35*N$28 -> 0 | ... R35: =$E35*R$28 -> 0 | S35: =E35-SUM(G35:R35) -> 0
A36: Eigen medewerkers | B36: MCB | C36: Medewerker Commerciële Binnendienst | D36: =_xlfn.XLOOKUP(B36,'report B_CategorieBoekjaar'!H:H,'report B_CategorieBoekjaar'!F:F,0) -> 56 | E36: =F36*D36 -> 0 | G36: =$E36*G$28 -> 0 | H36: =$E36*H$28 -> 0 | I36: =$E36*I$28 -> 0 | J36: =$E36*J$28 -> 0 | K36: =$E36*K$28 -> 0 | L36: =$E36*L$28 -> 0 | M36: =$E36*M$28 -> 0 | N36: =$E36*N$28 -> 0 | ... R36: =$E36*R$28 -> 0 | S36: =E36-SUM(G36:R36) -> 0
A37: Eigen medewerkers | B37: MS | C37: Medewerker Media Support | D37: =_xlfn.XLOOKUP(B37,'report B_CategorieBoekjaar'!H:H,'report B_CategorieBoekjaar'!F:F,0) -> 50 | E37: =F37*D37 -> 0 | G37: =$E37*G$28 -> 0 | H37: =$E37*H$28 -> 0 | I37: =$E37*I$28 -> 0 | J37: =$E37*J$28 -> 0 | K37: =$E37*K$28 -> 0 | L37: =$E37*L$28 -> 0 | M37: =$E37*M$28 -> 0 | N37: =$E37*N$28 -> 0 | ... R37: =$E37*R$28 -> 0 | S37: =E37-SUM(G37:R37) -> 0
A38: Eigen medewerkers | B38: PDO | C38: Productowner | D38: =_xlfn.XLOOKUP(B38,'report B_CategorieBoekjaar'!H:H,'report B_CategorieBoekjaar'!F:F,0) -> 87 | E38: =F38*D38 -> 0 | G38: =$E38*G$28 -> 0 | H38: =$E38*H$28 -> 0 | I38: =$E38*I$28 -> 0 | J38: =$E38*J$28 -> 0 | K38: =$E38*K$28 -> 0 | L38: =$E38*L$28 -> 0 | M38: =$E38*M$28 -> 0 | N38: =$E38*N$28 -> 0 | ... R38: =$E38*R$28 -> 0 | S38: =E38-SUM(G38:R38) -> 0
A39: Eigen medewerkers | B39: PRO | C39: Procesondersteuner/procesconsultants | D39: =_xlfn.XLOOKUP(B39,'report B_CategorieBoekjaar'!H:H,'report B_CategorieBoekjaar'!F:F,0) -> 56 | E39: =F39*D39 -> 0 | G39: =$E39*G$28 -> 0 | H39: =$E39*H$28 -> 0 | I39: =$E39*I$28 -> 0 | J39: =$E39*J$28 -> 0 | K39: =$E39*K$28 -> 0 | L39: =$E39*L$28 -> 0 | M39: =$E39*M$28 -> 0 | N39: =$E39*N$28 -> 0 | ... R39: =$E39*R$28 -> 0 | S39: =E39-SUM(G39:R39) -> 0
A40: Eigen medewerkers | B40: PS | C40: Proces Support | D40: =_xlfn.XLOOKUP(B40,'report B_CategorieBoekjaar'!H:H,'report B_CategorieBoekjaar'!F:F,0) -> 46 | E40: =F40*D40 -> 0 | G40: =$E40*G$28 -> 0 | H40: =$E40*H$28 -> 0 | I40: =$E40*I$28 -> 0 | J40: =$E40*J$28 -> 0 | K40: =$E40*K$28 -> 0 | L40: =$E40*L$28 -> 0 | M40: =$E40*M$28 -> 0 | N40: =$E40*N$28 -> 0 | ... R40: =$E40*R$28 -> 0 | S40: =E40-SUM(G40:R40) -> 0
A41: Eigen medewerkers | B41: TOE | C41: Toetsing | D41: =_xlfn.XLOOKUP(B41,'report B_CategorieBoekjaar'!H:H,'report B_CategorieBoekjaar'!F:F,0) -> 63 | E41: =F41*D41 -> 0 | G41: =$E41*G$28 -> 0 | H41: =$E41*H$28 -> 0 | I41: =$E41*I$28 -> 0 | J41: =$E41*J$28 -> 0 | K41: =$E41*K$28 -> 0 | L41: =$E41*L$28 -> 0 | M41: =$E41*M$28 -> 0 | N41: =$E41*N$28 -> 0 | ... R41: =$E41*R$28 -> 0 | S41: =E41-SUM(G41:R41) -> 0
A42: Eigen medewerkers | B42: TOM | C42: Toetsondersteunend medewerker | D42: =_xlfn.XLOOKUP(B42,'report B_CategorieBoekjaar'!H:H,'report B_CategorieBoekjaar'!F:F,0) -> 50 | E42: =F42*D42 -> 0 | G42: =$E42*G$28 -> 0 | H42: =$E42*H$28 -> 0 | I42: =$E42*I$28 -> 0 | J42: =$E42*J$28 -> 0 | K42: =$E42*K$28 -> 0 | L42: =$E42*L$28 -> 0 | M42: =$E42*M$28 -> 0 | N42: =$E42*N$28 -> 0 | ... R42: =$E42*R$28 -> 0 | S42: =E42-SUM(G42:R42) -> 0
... A54: Eigen medewerkers | B54: PJM | C54: Projectmanager | D54: =_xlfn.XLOOKUP(B54,'report B_CategorieBoekjaar'!H:H,'report B_CategorieBoekjaar'!F:F,0) -> 90 | E54: =F54*D54 -> 0 | G54: =$E54*G$28 -> 0 | H54: =$E54*H$28 -> 0 | I54: =$E54*I$28 -> 0 | J54: =$E54*J$28 -> 0 | K54: =$E54*K$28 -> 0 | L54: =$E54*L$28 -> 0 | M54: =$E54*M$28 -> 0 | N54: =$E54*N$28 -> 0 | ... R54: =$E54*R$28 -> 0 | S54: =E54-SUM(G54:R54) -> 0
A55: Inleen medewerkers | B55: DES | C55: =_xlfn.XLOOKUP(B55,$B$31:$B$54,$C$31:$C$54,0) -> Toetsdeskundige | D55: =_xlfn.XLOOKUP(B55,'report B_CategorieBoekjaar'!I:I,'report B_CategorieBoekjaar'!G:G,0) -> 109 | E55: =F55*D55 -> 0 | G55: =$E55*G$28 -> 0 | H55: =$E55*H$28 -> 0 | I55: =$E55*I$28 -> 0 | J55: =$E55*J$28 -> 0 | K55: =$E55*K$28 -> 0 | L55: =$E55*L$28 -> 0 | M55: =$E55*M$28 -> 0 | N55: =$E55*N$28 -> 0 | ... R55: =$E55*R$28 -> 0 | S55: =E55-SUM(G55:R55) -> 0
A56: Inleen medewerkers | B56: EA | C56: =_xlfn.XLOOKUP(B56,$B$31:$B$54,$C$31:$C$54,0) -> Enterprise Architect | D56: =_xlfn.XLOOKUP(B56,'report B_CategorieBoekjaar'!I:I,'report B_CategorieBoekjaar'!G:G,0) -> 116 | E56: =F56*D56 -> 0 | G56: =$E56*G$28 -> 0 | H56: =$E56*H$28 -> 0 | I56: =$E56*I$28 -> 0 | J56: =$E56*J$28 -> 0 | K56: =$E56*K$28 -> 0 | L56: =$E56*L$28 -> 0 | M56: =$E56*M$28 -> 0 | N56: =$E56*N$28 -> 0 | ... R56: =$E56*R$28 -> 0 | S56: =E56-SUM(G56:R56) -> 0
A57: Inleen medewerkers | B57: FUB | C57: =_xlfn.XLOOKUP(B57,$B$31:$B$54,$C$31:$C$54,0) -> Functioneel Beheerder | D57: =_xlfn.XLOOKUP(B57,'report B_CategorieBoekjaar'!I:I,'report B_CategorieBoekjaar'!G:G,0) -> 102 | E57: =F57*D57 -> 0 | G57: =$E57*G$28 -> 0 | H57: =$E57*H$28 -> 0 | I57: =$E57*I$28 -> 0 | J57: =$E57*J$28 -> 0 | K57: =$E57*K$28 -> 0 | L57: =$E57*L$28 -> 0 | M57: =$E57*M$28 -> 0 | N57: =$E57*N$28 -> 0 | ... R57: =$E57*R$28 -> 0 | S57: =E57-SUM(G57:R57) -> 0
...

Sheet Stamgegevens projecten
A1: projectnaam | B1: projectnummer | C1: ingangsdatum | D1: einddatum | E1: koptekst project | F1: vertaling projectgroep | G1: vertaling PL | H1: vertaling controller | I1: vertaling verkoopleider | J1: klantrekening | K1: klantnaam | L1: projectcontract | M1: Dimensie | N1: BTW | O1: sorteerveld 1 | P1: sorteerveld 2 | Q1: sorteerveld 3 | R1: projectnaam
A2: =Projectbegroting!$B$8 -> Klant in zicht 2027 | B2: =Projectbegroting!$B$9 -> 30626-0003 | C2: =Projectbegroting!B10 -> 46388 | D2: =Projectbegroting!B11 -> 46752 | E2: No | F2: =Projectbegroting!B18 -> Kosten | G2: 41265 | H2: 42805 | I2: 34955 | J2: =Projectbegroting!B24 -> 10021301 | K2: =Projectbegroting!B25 -> Cito | L2: =Projectbegroting!B26 -> 2000000 | M2: ="-"&Projectbegroting!B19&"-"&Projectbegroting!B20&"-"&Projectbegroting!B21&"-"&Projectbegroting!B9&"-" -> -7040---30626-0003- | N2: =Projectbegroting!B22 -> NL-B | O2: =Projectbegroting!B16 -> AUT-POC | R2: =Projectbegroting!$B$8 -> Klant in zicht 2027
A7: * Let op als er geen hoofdproject is dan ook een hoofdproject op dit overzicht meenemen (dus geen projectnummers vorig jaar).

Sheet ETC regels projecten
A1: hulpkolom | C1: Projectnaam | D1: AXnr | E1: Meerjarig | F1: Omzet | G1: Opmerkingen | H1: Categorie | I1: Aantal | J1: Prijs | K1: Bedrag
A2: =CONCATENATE(D2,H2) -> 30626-0003AM | C2: =Projectbegroting!$B$8 -> Klant in zicht 2027 | D2: =Projectbegroting!$B$9 -> 30626-0003 | H2: AM | I2: =Projectbegroting!F31 -> 0 | J2: =Projectbegroting!D31 -> 81 | K2: =Projectbegroting!E31 -> 0
A3: =CONCATENATE(D3,H3) -> 30626-0003BU | C3: =Projectbegroting!$B$8 -> Klant in zicht 2027 | D3: =Projectbegroting!$B$9 -> 30626-0003 | H3: BU | I3: =Projectbegroting!F32 -> 0 | J3: =Projectbegroting!D32 -> 64 | K3: =Projectbegroting!E32 -> 0
A4: =CONCATENATE(D4,H4) -> 30626-0003CM | C4: =Projectbegroting!$B$8 -> Klant in zicht 2027 | D4: =Projectbegroting!$B$9 -> 30626-0003 | H4: CM | I4: =Projectbegroting!F33 -> 0 | J4: =Projectbegroting!D33 -> 80 | K4: =Projectbegroting!E33 -> 0
A5: =CONCATENATE(D5,H5) -> 30626-0003CS | C5: =Projectbegroting!$B$8 -> Klant in zicht 2027 | D5: =Projectbegroting!$B$9 -> 30626-0003 | H5: CS | I5: =Projectbegroting!F34 -> 0 | J5: =Projectbegroting!D34 -> 64 | K5: =Projectbegroting!E34 -> 0
A6: =CONCATENATE(D6,H6) -> 30626-0003DES | C6: =Projectbegroting!$B$8 -> Klant in zicht 2027 | D6: =Projectbegroting!$B$9 -> 30626-0003 | H6: DES | I6: =Projectbegroting!F35 -> 0 | J6: =Projectbegroting!D35 -> 77 | K6: =Projectbegroting!E35 -> 0
A7: =CONCATENATE(D7,H7) -> 30626-0003MCB | C7: =Projectbegroting!$B$8 -> Klant in zicht 2027 | D7: =Projectbegroting!$B$9 -> 30626-0003 | H7: MCB | I7: =Projectbegroting!F36 -> 0 | J7: =Projectbegroting!D36 -> 56 | K7: =Projectbegroting!E36 -> 0
A8: =CONCATENATE(D8,H8) -> 30626-0003MS | C8: =Projectbegroting!$B$8 -> Klant in zicht 2027 | D8: =Projectbegroting!$B$9 -> 30626-0003 | H8: MS | I8: =Projectbegroting!F37 -> 0 | J8: =Projectbegroting!D37 -> 50 | K8: =Projectbegroting!E37 -> 0
A9: =CONCATENATE(D9,H9) -> 30626-0003PDO | C9: =Projectbegroting!$B$8 -> Klant in zicht 2027 | D9: =Projectbegroting!$B$9 -> 30626-0003 | H9: PDO | I9: =Projectbegroting!F38 -> 0 | J9: =Projectbegroting!D38 -> 87 | K9: =Projectbegroting!E38 -> 0
A10: =CONCATENATE(D10,H10) -> 30626-0003PRO | C10: =Projectbegroting!$B$8 -> Klant in zicht 2027 | D10: =Projectbegroting!$B$9 -> 30626-0003 | H10: PRO | I10: =Projectbegroting!F39 -> 0 | J10: =Projectbegroting!D39 -> 56 | K10: =Projectbegroting!E39 -> 0
A11: =CONCATENATE(D11,H11) -> 30626-0003PS | C11: =Projectbegroting!$B$8 -> Klant in zicht 2027 | D11: =Projectbegroting!$B$9 -> 30626-0003 | H11: PS | I11: =Projectbegroting!F40 -> 0 | J11: =Projectbegroting!D40 -> 46 | K11: =Projectbegroting!E40 -> 0
A12: =CONCATENATE(D12,H12) -> 30626-0003TOE | C12: =Projectbegroting!$B$8 -> Klant in zicht 2027 | D12: =Projectbegroting!$B$9 -> 30626-0003 | H12: TOE | I12: =Projectbegroting!F41 -> 0 | J12: =Projectbegroting!D41 -> 63 | K12: =Projectbegroting!E41 -> 0
A13: =CONCATENATE(D13,H13) -> 30626-0003TOM | C13: =Projectbegroting!$B$8 -> Klant in zicht 2027 | D13: =Projectbegroting!$B$9 -> 30626-0003 | H13: TOM | I13: =Projectbegroting!F42 -> 0 | J13: =Projectbegroting!D42 -> 50 | K13: =Projectbegroting!E42 -> 0
... A67: =CONCATENATE(D67,H67) -> 30626-0003730 | C67: =Projectbegroting!$B$8 -> Klant in zicht 2027 | D67: =Projectbegroting!$B$9 -> 30626-0003 | H67: 730 | I67: =Projectbegroting!F96 -> 0 | J67: =Projectbegroting!D96 -> 0.05 | K67: =Projectbegroting!E96 -> 0
A68: =CONCATENATE(D68,H68) -> 30626-0003740 | B68: =""&Projectbegroting!F65 | C68: =Projectbegroting!$B$8 -> Klant in zicht 2027 | D68: =Projectbegroting!$B$9 -> 30626-0003 | H68: 740 | I68: =Projectbegroting!F97 -> 1 | J68: =Projectbegroting!D97 -> 0 | K68: =Projectbegroting!E97 -> 0
A69: =CONCATENATE(D69,H69) -> 30626-0003843 | C69: =Projectbegroting!$B$8 -> Klant in zicht 2027 | D69: =Projectbegroting!$B$9 -> 30626-0003 | H69: 843 | I69: =Projectbegroting!F98 -> 1 | J69: =Projectbegroting!D98 -> 0 | K69: =Projectbegroting!E98 -> 0

Sheet Probuto
A1: Rekening | B1: Kostenplaats | C1: Kostendrager | D1: variant | E1: jan | F1: feb | G1: maart | H1: april | I1: mei | J1: juni | K1: juli | L1: aug | M1: sep | N1: okt | O1: nov | P1: dec
A2: 8320 | B2: =IF(Projectbegroting!$B$18=Lijsten!$T$2,Projectbegroting!$B$19,"") | C2: =IF(Projectbegroting!$B$18=Lijsten!$T$2,Projectbegroting!$B$20,"") | D2: =IF(Projectbegroting!$B$18=Lijsten!$T$2,Projectbegroting!$B$21,"") | E2: =IFERROR(-IF(OR(Projectbegroting!$B$18=Lijsten!$T$2,Projectbegroting!$B$18=Lijsten!$W$2),SUMIF(Projectbegroting!$A:$A,"omzet",Projectbegroting!G:G),""),"") | F2: =IFERROR(-IF(OR(Projectbegroting!$B$18=Lijsten!$T$2,Projectbegroting!$B$18=Lijsten!$W$2),SUMIF(Projectbegroting!$A:$A,"omzet",Projectbegroting!H:H),""),"") | G2: =IFERROR(-IF(OR(Projectbegroting!$B$18=Lijsten!$T$2,Projectbegroting!$B$18=Lijsten!$W$2),SUMIF(Projectbegroting!$A:$A,"omzet",Projectbegroting!I:I),""),"") | H2: =IFERROR(-IF(OR(Projectbegroting!$B$18=Lijsten!$T$2,Projectbegroting!$B$18=Lijsten!$W$2),SUMIF(Projectbegroting!$A:$A,"omzet",Projectbegroting!J:J),""),"") | I2: =IFERROR(-IF(OR(Projectbegroting!$B$18=Lijsten!$T$2,Projectbegroting!$B$18=Lijsten!$W$2),SUMIF(Projectbegroting!$A:$A,"omzet",Projectbegroting!K:K),""),"") | J2: =IFERROR(-IF(OR(Projectbegroting!$B$18=Lijsten!$T$2,Projectbegroting!$B$18=Lijsten!$W$2),SUMIF(Projectbegroting!$A:$A,"omzet",Projectbegroting!L:L),""),"") | K2: =IFERROR(-IF(OR(Projectbegroting!$B$18=Lijsten!$T$2,Projectbegroting!$B$18=Lijsten!$W$2),SUMIF(Projectbegroting!$A:$A,"omzet",Projectbegroting!M:M),""),"") | L2: =IFERROR(-IF(OR(Projectbegroting!$B$18=Lijsten!$T$2,Projectbegroting!$B$18=Lijsten!$W$2),SUMIF(Projectbegroting!$A:$A,"omzet",Projectbegroting!N:N),""),"") | M2: =IFERROR(-IF(OR(Projectbegroting!$B$18=Lijsten!$T$2,Projectbegroting!$B$18=Lijsten!$W$2),SUMIF(Projectbegroting!$A:$A,"omzet",Projectbegroting!O:O),""),"") | N2: =IFERROR(-IF(OR(Projectbegroting!$B$18=Lijsten!$T$2,Projectbegroting!$B$18=Lijsten!$W$2),SUMIF(Projectbegroting!$A:$A,"omzet",Projectbegroting!P:P),""),"") | O2: =IFERROR(-IF(OR(Projectbegroting!$B$18=Lijsten!$T$2,Projectbegroting!$B$18=Lijsten!$W$2),SUMIF(Projectbegroting!$A:$A,"omzet",Projectbegroting!Q:Q),""),"") | P2: =IFERROR(-IF(OR(Projectbegroting!$B$18=Lijsten!$T$2,Projectbegroting!$B$18=Lijsten!$W$2),SUMIF(Projectbegroting!$A:$A,"omzet",Projectbegroting!R:R),""),"")
A3: 4700 | B3: =IF(Projectbegroting!$B$18=Lijsten!$T$2,Projectbegroting!$B$19,"") | C3: =IF(Projectbegroting!$B$18=Lijsten!$T$2,Projectbegroting!$B$20,"") | D3: =IF(Projectbegroting!$B$18=Lijsten!$T$2,Projectbegroting!$B$21,"") | E3: =IF(Projectbegroting!$B$18=Lijsten!$T$2,SUMIF(Projectbegroting!$A:$A,"Onkosten",Projectbegroting!G:G),"") | F3: =IF(Projectbegroting!$B$18=Lijsten!$T$2,SUMIF(Projectbegroting!$A:$A,"Onkosten",Projectbegroting!H:H),"") | G3: =IF(Projectbegroting!$B$18=Lijsten!$T$2,SUMIF(Projectbegroting!$A:$A,"Onkosten",Projectbegroting!I:I),"") | H3: =IF(Projectbegroting!$B$18=Lijsten!$T$2,SUMIF(Projectbegroting!$A:$A,"Onkosten",Projectbegroting!J:J),"") | I3: =IF(Projectbegroting!$B$18=Lijsten!$T$2,SUMIF(Projectbegroting!$A:$A,"Onkosten",Projectbegroting!K:K),"") | J3: =IF(Projectbegroting!$B$18=Lijsten!$T$2,SUMIF(Projectbegroting!$A:$A,"Onkosten",Projectbegroting!L:L),"") | K3: =IF(Projectbegroting!$B$18=Lijsten!$T$2,SUMIF(Projectbegroting!$A:$A,"Onkosten",Projectbegroting!M:M),"") | L3: =IF(Projectbegroting!$B$18=Lijsten!$T$2,SUMIF(Projectbegroting!$A:$A,"Onkosten",Projectbegroting!N:N),"") | M3: =IF(Projectbegroting!$B$18=Lijsten!$T$2,SUMIF(Projectbegroting!$A:$A,"Onkosten",Projectbegroting!O:O),"") | N3: =IF(Projectbegroting!$B$18=Lijsten!$T$2,SUMIF(Projectbegroting!$A:$A,"Onkosten",Projectbegroting!P:P),"") | O3: =IF(Projectbegroting!$B$18=Lijsten!$T$2,SUMIF(Projectbegroting!$A:$A,"Onkosten",Projectbegroting!Q:Q),"") | P3: =IF(Projectbegroting!$B$18=Lijsten!$T$2,SUMIF(Projectbegroting!$A:$A,"Onkosten",Projectbegroting!R:R),"")
A4: 4703 | B4: =IF(Projectbegroting!$B$18=Lijsten!$W$2,Projectbegroting!$B$19,"") -> 7040 | C4: =IF(Projectbegroting!$B$18=Lijsten!$W$2,Projectbegroting!$B$20,"") -> 0 | D4: =IF(Projectbegroting!$B$18=Lijsten!$W$2,Projectbegroting!$B$21,"") -> 0 | E4: =IF(Projectbegroting!$B$18=Lijsten!$W$2,SUMIF(Projectbegroting!$A:$A,"Onkosten",Projectbegroting!G:G)+SUMIF(Projectbegroting!$A:$A,"Inleen medewerkers",Projectbegroting!G:G),"") -> 0 | F4: =IF(Projectbegroting!$B$18=Lijsten!$W$2,SUMIF(Projectbegroting!$A:$A,"Onkosten",Projectbegroting!H:H)+SUMIF(Projectbegroting!$A:$A,"Inleen medewerkers",Projectbegroting!H:H),"") -> 0 | G4: =IF(Projectbegroting!$B$18=Lijsten!$W$2,SUMIF(Projectbegroting!$A:$A,"Onkosten",Projectbegroting!I:I)+SUMIF(Projectbegroting!$A:$A,"Inleen medewerkers",Projectbegroting!I:I),"") -> 0 | H4: =IF(Projectbegroting!$B$18=Lijsten!$W$2,SUMIF(Projectbegroting!$A:$A,"Onkosten",Projectbegroting!J:J)+SUMIF(Projectbegroting!$A:$A,"Inleen medewerkers",Projectbegroting!J:J),"") -> 0 | I4: =IF(Projectbegroting!$B$18=Lijsten!$W$2,SUMIF(Projectbegroting!$A:$A,"Onkosten",Projectbegroting!K:K)+SUMIF(Projectbegroting!$A:$A,"Inleen medewerkers",Projectbegroting!K:K),"") -> 0 | J4: =IF(Projectbegroting!$B$18=Lijsten!$W$2,SUMIF(Projectbegroting!$A:$A,"Onkosten",Projectbegroting!L:L)+SUMIF(Projectbegroting!$A:$A,"Inleen medewerkers",Projectbegroting!L:L),"") -> 0 | K4: =IF(Projectbegroting!$B$18=Lijsten!$W$2,SUMIF(Projectbegroting!$A:$A,"Onkosten",Projectbegroting!M:M)+SUMIF(Projectbegroting!$A:$A,"Inleen medewerkers",Projectbegroting!M:M),"") -> 0 | L4: =IF(Projectbegroting!$B$18=Lijsten!$W$2,SUMIF(Projectbegroting!$A:$A,"Onkosten",Projectbegroting!N:N)+SUMIF(Projectbegroting!$A:$A,"Inleen medewerkers",Projectbegroting!N:N),"") -> 0 | M4: =IF(Projectbegroting!$B$18=Lijsten!$W$2,SUMIF(Projectbegroting!$A:$A,"Onkosten",Projectbegroting!O:O)+SUMIF(Projectbegroting!$A:$A,"Inleen medewerkers",Projectbegroting!O:O),"") -> 0 | N4: =IF(Projectbegroting!$B$18=Lijsten!$W$2,SUMIF(Projectbegroting!$A:$A,"Onkosten",Projectbegroting!P:P)+SUMIF(Projectbegroting!$A:$A,"Inleen medewerkers",Projectbegroting!P:P),"") -> 0 | O4: =IF(Projectbegroting!$B$18=Lijsten!$W$2,SUMIF(Projectbegroting!$A:$A,"Onkosten",Projectbegroting!Q:Q)+SUMIF(Projectbegroting!$A:$A,"Inleen medewerkers",Projectbegroting!Q:Q),"") -> 0 | P4: =IF(Projectbegroting!$B$18=Lijsten!$W$2,SUMIF(Projectbegroting!$A:$A,"Onkosten",Projectbegroting!R:R)+SUMIF(Projectbegroting!$A:$A,"Inleen medewerkers",Projectbegroting!R:R),"") -> 0
A5: 4705 | B5: =IF(OR(Projectbegroting!$B$18=Lijsten!$T$2),Projectbegroting!B19,"") | C5: =IF(OR(Projectbegroting!$B$18=Lijsten!$T$2),Projectbegroting!B20,"") | D5: =IF(OR(Projectbegroting!$B$18=Lijsten!$T$2),Projectbegroting!B21,"") | E5: =IFERROR(IF(OR(Projectbegroting!$B$18=Lijsten!$T$2),SUMIF(Projectbegroting!$A:$A,"Inleen medewerkers",Projectbegroting!G:G),""),"") | F5: =IFERROR(IF(OR(Projectbegroting!$B$18=Lijsten!$T$2),SUMIF(Projectbegroting!$A:$A,"Inleen medewerkers",Projectbegroting!H:H),""),"") | G5: =IFERROR(IF(OR(Projectbegroting!$B$18=Lijsten!$T$2),SUMIF(Projectbegroting!$A:$A,"Inleen medewerkers",Projectbegroting!I:I),""),"") | H5: =IFERROR(IF(OR(Projectbegroting!$B$18=Lijsten!$T$2),SUMIF(Projectbegroting!$A:$A,"Inleen medewerkers",Projectbegroting!J:J),""),"") | I5: =IFERROR(IF(OR(Projectbegroting!$B$18=Lijsten!$T$2),SUMIF(Projectbegroting!$A:$A,"Inleen medewerkers",Projectbegroting!K:K),""),"") | J5: =IFERROR(IF(OR(Projectbegroting!$B$18=Lijsten!$T$2),SUMIF(Projectbegroting!$A:$A,"Inleen medewerkers",Projectbegroting!L:L),""),"") | K5: =IFERROR(IF(OR(Projectbegroting!$B$18=Lijsten!$T$2),SUMIF(Projectbegroting!$A:$A,"Inleen medewerkers",Projectbegroting!M:M),""),"") | L5: =IFERROR(IF(OR(Projectbegroting!$B$18=Lijsten!$T$2),SUMIF(Projectbegroting!$A:$A,"Inleen medewerkers",Projectbegroting!N:N),""),"") | M5: =IFERROR(IF(OR(Projectbegroting!$B$18=Lijsten!$T$2),SUMIF(Projectbegroting!$A:$A,"Inleen medewerkers",Projectbegroting!O:O),""),"") | N5: =IFERROR(IF(OR(Projectbegroting!$B$18=Lijsten!$T$2),SUMIF(Projectbegroting!$A:$A,"Inleen medewerkers",Projectbegroting!P:P),""),"") | O5: =IFERROR(IF(OR(Projectbegroting!$B$18=Lijsten!$T$2),SUMIF(Projectbegroting!$A:$A,"Inleen medewerkers",Projectbegroting!Q:Q),""),"") | P5: =IFERROR(IF(OR(Projectbegroting!$B$18=Lijsten!$T$2),SUMIF(Projectbegroting!$A:$A,"Inleen medewerkers",Projectbegroting!R:R),""),"")
A6: 4710 | B6: =IF(Projectbegroting!$B$18=Lijsten!$Z$2,Projectbegroting!$B$19,"") | C6: =IF(Projectbegroting!$B$18=Lijsten!$Z$2,Projectbegroting!$B$20,"") | D6: =IF(Projectbegroting!$B$18=Lijsten!$Z$2,Projectbegroting!$B$21,"") | E6: =IF(Projectbegroting!$B$18=Lijsten!$Z$2,SUMIF(Projectbegroting!$A:$A,"Onkosten",Projectbegroting!G:G)+SUMIF(Projectbegroting!$A:$A,"Inleen medewerkers",Projectbegroting!G:G),"") | F6: =IF(Projectbegroting!$B$18=Lijsten!$Z$2,SUMIF(Projectbegroting!$A:$A,"Onkosten",Projectbegroting!H:H)+SUMIF(Projectbegroting!$A:$A,"Inleen medewerkers",Projectbegroting!H:H),"") | G6: =IF(Projectbegroting!$B$18=Lijsten!$Z$2,SUMIF(Projectbegroting!$A:$A,"Onkosten",Projectbegroting!I:I)+SUMIF(Projectbegroting!$A:$A,"Inleen medewerkers",Projectbegroting!I:I),"") | H6: =IF(Projectbegroting!$B$18=Lijsten!$Z$2,SUMIF(Projectbegroting!$A:$A,"Onkosten",Projectbegroting!J:J)+SUMIF(Projectbegroting!$A:$A,"Inleen medewerkers",Projectbegroting!J:J),"") | I6: =IF(Projectbegroting!$B$18=Lijsten!$Z$2,SUMIF(Projectbegroting!$A:$A,"Onkosten",Projectbegroting!K:K)+SUMIF(Projectbegroting!$A:$A,"Inleen medewerkers",Projectbegroting!K:K),"") | J6: =IF(Projectbegroting!$B$18=Lijsten!$Z$2,SUMIF(Projectbegroting!$A:$A,"Onkosten",Projectbegroting!L:L)+SUMIF(Projectbegroting!$A:$A,"Inleen medewerkers",Projectbegroting!L:L),"") | K6: =IF(Projectbegroting!$B$18=Lijsten!$Z$2,SUMIF(Projectbegroting!$A:$A,"Onkosten",Projectbegroting!M:M)+SUMIF(Projectbegroting!$A:$A,"Inleen medewerkers",Projectbegroting!M:M),"") | L6: =IF(Projectbegroting!$B$18=Lijsten!$Z$2,SUMIF(Projectbegroting!$A:$A,"Onkosten",Projectbegroting!N:N)+SUMIF(Projectbegroting!$A:$A,"Inleen medewerkers",Projectbegroting!N:N),"") | M6: =IF(Projectbegroting!$B$18=Lijsten!$Z$2,SUMIF(Projectbegroting!$A:$A,"Onkosten",Projectbegroting!O:O)+SUMIF(Projectbegroting!$A:$A,"Inleen medewerkers",Projectbegroting!O:O),"") | N6: =IF(Projectbegroting!$B$18=Lijsten!$Z$2,SUMIF(Projectbegroting!$A:$A,"Onkosten",Projectbegroting!P:P)+SUMIF(Projectbegroting!$A:$A,"Inleen medewerkers",Projectbegroting!P:P),"") | O6: =IF(Projectbegroting!$B$18=Lijsten!$Z$2,SUMIF(Projectbegroting!$A:$A,"Onkosten",Projectbegroting!Q:Q)+SUMIF(Projectbegroting!$A:$A,"Inleen medewerkers",Projectbegroting!Q:Q),"") | P6: =IF(Projectbegroting!$B$18=Lijsten!$Z$2,SUMIF(Projectbegroting!$A:$A,"Onkosten",Projectbegroting!R:R)+SUMIF(Projectbegroting!$A:$A,"Inleen medewerkers",Projectbegroting!R:R),"")
A7: 5500 | B7: =IF(OR(Projectbegroting!B18=Lijsten!T2,Projectbegroting!B18=Lijsten!W2),Projectbegroting!B19,"") -> 7040 | C7: =IF(OR(Projectbegroting!B18=Lijsten!T2,Projectbegroting!B18=Lijsten!W2),Projectbegroting!B20,"") -> 0 | D7: =IF(OR(Projectbegroting!B18=Lijsten!T2,Projectbegroting!B18=Lijsten!W2),Projectbegroting!B21,"") -> 0 | E7: =IF(OR(Projectbegroting!$B$18=Lijsten!$T$2,Projectbegroting!$B$18=Lijsten!$W$2),SUMIF(Projectbegroting!$A:$A,"Eigen medewerkers",Projectbegroting!G:G),"") -> 0 | F7: =IF(OR(Projectbegroting!$B$18=Lijsten!$T$2,Projectbegroting!$B$18=Lijsten!$W$2),SUMIF(Projectbegroting!$A:$A,"Eigen medewerkers",Projectbegroting!H:H),"") -> 0 | G7: =IF(OR(Projectbegroting!$B$18=Lijsten!$T$2,Projectbegroting!$B$18=Lijsten!$W$2),SUMIF(Projectbegroting!$A:$A,"Eigen medewerkers",Projectbegroting!I:I),"") -> 0 | H7: =IF(OR(Projectbegroting!$B$18=Lijsten!$T$2,Projectbegroting!$B$18=Lijsten!$W$2),SUMIF(Projectbegroting!$A:$A,"Eigen medewerkers",Projectbegroting!J:J),"") -> 0 | I7: =IF(OR(Projectbegroting!$B$18=Lijsten!$T$2,Projectbegroting!$B$18=Lijsten!$W$2),SUMIF(Projectbegroting!$A:$A,"Eigen medewerkers",Projectbegroting!K:K),"") -> 0 | J7: =IF(OR(Projectbegroting!$B$18=Lijsten!$T$2,Projectbegroting!$B$18=Lijsten!$W$2),SUMIF(Projectbegroting!$A:$A,"Eigen medewerkers",Projectbegroting!L:L),"") -> 0 | K7: =IF(OR(Projectbegroting!$B$18=Lijsten!$T$2,Projectbegroting!$B$18=Lijsten!$W$2),SUMIF(Projectbegroting!$A:$A,"Eigen medewerkers",Projectbegroting!M:M),"") -> 0 | L7: =IF(OR(Projectbegroting!$B$18=Lijsten!$T$2,Projectbegroting!$B$18=Lijsten!$W$2),SUMIF(Projectbegroting!$A:$A,"Eigen medewerkers",Projectbegroting!N:N),"") -> 0 | M7: =IF(OR(Projectbegroting!$B$18=Lijsten!$T$2,Projectbegroting!$B$18=Lijsten!$W$2),SUMIF(Projectbegroting!$A:$A,"Eigen medewerkers",Projectbegroting!O:O),"") -> 0 | N7: =IF(OR(Projectbegroting!$B$18=Lijsten!$T$2,Projectbegroting!$B$18=Lijsten!$W$2),SUMIF(Projectbegroting!$A:$A,"Eigen medewerkers",Projectbegroting!P:P),"") -> 0 | O7: =IF(OR(Projectbegroting!$B$18=Lijsten!$T$2,Projectbegroting!$B$18=Lijsten!$W$2),SUMIF(Projectbegroting!$A:$A,"Eigen medewerkers",Projectbegroting!Q:Q),"") -> 0 | P7: =IF(OR(Projectbegroting!$B$18=Lijsten!$T$2,Projectbegroting!$B$18=Lijsten!$W$2),SUMIF(Projectbegroting!$A:$A,"Eigen medewerkers",Projectbegroting!R:R),"") -> 0
A8: 5501 | B8: =IF(Projectbegroting!$B$18=Lijsten!$Z$2,Projectbegroting!$B$19,"") | C8: =IF(Projectbegroting!$B$18=Lijsten!$Z$2,Projectbegroting!$B$20,"") | D8: =IF(Projectbegroting!$B$18=Lijsten!$Z$2,Projectbegroting!$B$21,"") | E8: =IF(Projectbegroting!$B$18=Lijsten!$Z$2,SUMIF(Projectbegroting!$A:$A,"Eigen medewerkers",Projectbegroting!G:G),"") | F8: =IF(Projectbegroting!$B$18=Lijsten!$Z$2,SUMIF(Projectbegroting!$A:$A,"Eigen medewerkers",Projectbegroting!H:H),"") | G8: =IF(Projectbegroting!$B$18=Lijsten!$Z$2,SUMIF(Projectbegroting!$A:$A,"Eigen medewerkers",Projectbegroting!I:I),"") | H8: =IF(Projectbegroting!$B$18=Lijsten!$Z$2,SUMIF(Projectbegroting!$A:$A,"Eigen medewerkers",Projectbegroting!J:J),"") | I8: =IF(Projectbegroting!$B$18=Lijsten!$Z$2,SUMIF(Projectbegroting!$A:$A,"Eigen medewerkers",Projectbegroting!K:K),"") | J8: =IF(Projectbegroting!$B$18=Lijsten!$Z$2,SUMIF(Projectbegroting!$A:$A,"Eigen medewerkers",Projectbegroting!L:L),"") | K8: =IF(Projectbegroting!$B$18=Lijsten!$Z$2,SUMIF(Projectbegroting!$A:$A,"Eigen medewerkers",Projectbegroting!M:M),"") | L8: =IF(Projectbegroting!$B$18=Lijsten!$Z$2,SUMIF(Projectbegroting!$A:$A,"Eigen medewerkers",Projectbegroting!N:N),"") | M8: =IF(Projectbegroting!$B$18=Lijsten!$Z$2,SUMIF(Projectbegroting!$A:$A,"Eigen medewerkers",Projectbegroting!O:O),"") | N8: =IF(Projectbegroting!$B$18=Lijsten!$Z$2,SUMIF(Projectbegroting!$A:$A,"Eigen medewerkers",Projectbegroting!P:P),"") | O8: =IF(Projectbegroting!$B$18=Lijsten!$Z$2,SUMIF(Projectbegroting!$A:$A,"Eigen medewerkers",Projectbegroting!Q:Q),"") | P8: =IF(Projectbegroting!$B$18=Lijsten!$Z$2,SUMIF(Projectbegroting!$A:$A,"Eigen medewerkers",Projectbegroting!R:R),"")
A9: 5600 | B9: =B7 -> 7040 | E9: =IFERROR(-E7,"") -> 0 | F9: =IFERROR(-F7,"") -> 0 | G9: =IFERROR(-G7,"") -> 0 | H9: =IFERROR(-H7,"") -> 0 | I9: =IFERROR(-I7,"") -> 0 | J9: =IFERROR(-J7,"") -> 0 | K9: =IFERROR(-K7,"") -> 0 | L9: =IFERROR(-L7,"") -> 0 | ... P9: =IFERROR(-P7,"") -> 0
A10: 5601 | B10: =B8 | E10: =IFERROR(-E8,"") | F10: =IFERROR(-F8,"") | G10: =IFERROR(-G8,"") | H10: =IFERROR(-H8,"") | I10: =IFERROR(-I8,"") | J10: =IFERROR(-J8,"") | K10: =IFERROR(-K8,"") | L10: =IFERROR(-L8,"") | ... P10: =IFERROR(-P8,"")
B11: =B8 | E11: =IFERROR(-E8,"") | F11: =IFERROR(-F8,"") | G11: =IFERROR(-G8,"") | H11: =IFERROR(-H8,"") | I11: =IFERROR(-I8,"") | J11: =IFERROR(-J8,"") | K11: =IFERROR(-K8,"") | L11: =IFERROR(-L8,"") | ... P11: =IFERROR(-P8,"")

Sheet Lijsten
A2: Projectgroep | C2: Kostenplaats | E2: Kostendrager | G2: Variant | I2: BTW-Code | K2: Controller | N2: Projectleider | Q2: Opdrachtgever | T2: OiOvD | W2: Kosten | Z2: Invest
A3: Invest - Investeringsprojecten | C3: 5110 - Uitgeverij PO Belast | I3: EU-B; export binnen eu belast | K3: Elise Borgers | L3: 42805 | N3: Anja de Wijs | O3: 1180 | Q3: Alma van Til | R3: 1160 | T3: Eigen medewerkers | U3: 5500 | W3: Eigen medewerkers | X3: 5500 | Z3: Eigen medewerkers | AA3: 5501
A4: Kosten - Beheeractiviteiten | C4: 5111 - Uitgeverij PO Vrijgesteld | E4: KIB | G4: DUI | I4: EX-B ; export buiten eu belast | K4: Steef Berkeljon | L4: 43515 | N4: Anne Hettema | O4: 24745 | Q4: Frans van Dijk | R4: 30425 | T4: Inleen medewerkers | U4: 4705 | W4: Inleen medewerkers | X4: 4703 | Z4: Inleen medewerkers | AA4: 4710
A5: OiOvD - Ontwikkeling in opdracht van derden | C5: 5120 - Uitgeverij VO Belast | E5: LIBDST | G5: ENG | I5: EX-V ; export buiten ex vrijgesteld | K5: George Pavel | L5: 2061 | N5: Antoinette van het Hul - Derksen | O5: 3097 | Q5: Jasper Kwakkelstein | R5: 2950 | T5: Onkosten | U5: 4700 | W5: Onkosten | X5: 4703 | Z5: Onkosten | AA5: 4710
C6: 5121 - Uitgeverij VO Vrijgesteld | E6: LIBLVS | G6: FRA | I6: NL-B ; btw belast hoog | K6: Tim Visser | L6: 29845 | N6: Asther den Boogert | O6: 2718 | Q6: Joanne van Emmerik | R6: 2815 | T6: Omzet | U6: 8320 | W6: Omzet | X6: 8320 | Z6: Omzet | AA6: 8320
C7: 5310 - Professionals Belast | E7: TRAINCERTPO | G7: NED | I7: NL-P ; btw belast hoog prorata | N7: Frans van Dijk | O7: 30425 | Q7: Marc van der Lee | R7: 9005
C8: 5311 - Professionals Vrijgesteld | E8: CVVO | G8: SPA | I8: NL-V ; btw vrijgesteld | N8: Hanneke Bouwmans - de Jong | O8: 2131 | Q8: Rianne Hommelberg | R8: 24255
C9: 5520 - Proces support | E9: KLT | G9: PABOPAR | N9: Jasper de Vries | O9: 34495 | Q9: Aufa Ramdani | R9: 21825
C10: 5530 - Media support | E10: TRAINCERTVO | G10: PABOVH | N10: Jasper Kwakkelstein | O10: 2950 | Q10: Saila Kiriwenno - Dovermann | R10: 35055
C11: 5570 - Trainers | E11: BONDERW | G11: TRAINCERT | N11: Jill Linders | O11: 24105 | Q11: Manon Heesen | R11: 3390
C12: 5621 - Buitendienst POVO | E12: ONDERZOEK | G12: PEIL | N12: Joanne van Emmerik | O12: 2815 | Q12: Jan Spruijt | R12: 35505
C13: 5622 - Binnendienst POVO | E13: TALEN | G13: INBU | N13: Jossie Hunting | O13: 30775 | Q13: Dennis van den Broek | R13: 2712
C14: 5630 - Klantenservice | E14: ZM | G14: STEX | N14: Kathelijn Zwols | O14: 11895 | Q14: Marijn Krijgsman | R14: 34955
C15: 5720 - Staf | G15: NATURALISATIE | N15: Loes van den Heuvel | O15: 13495 | Q15: Judith Vloedgraven | R15: 2522
C16: 6010 - Data & Tech | G16: BODEM | N16: Manon Heesen | O16: 3390 | Q16: Bert Thijs de Jong | R16: 34815
C17: 7020 - Overhead Onbelast | G17: CDD | N17: Onne Smeets | O17: 36625 | Q17: Cornelis Richter | R17: 41265
C18: 7040 - Overhead Belast | G18: ISSOEPA | N18: Nienke Elijzen | O18: 31935 | Q18: Jorine Vermeulen | R18: 24945
C19: 9545 - IVIT BV (BTW vrij) | G19: ISSOLPA | N19: Peter van der Leek | O19: 32085 | Q19: Leontine Derks | R19: 36555
C20: 9546 - IVIT BV (belast) | G20: LASSER | N20: Rianne Hommelberg | O20: 24255 | Q20: Manon Heesen | R20: 3390
G21: MEDREK | N21: Rick te Kloeze | O21: 2926 | Q21: Rick Godschalk | R21: 2931
G22: NBA | N22: Rozanne Drexler | O22: 3064 | Q22: Esther Scolten | R22: 41725
G23: NCTV | N23: Sanne Lecluijze | O23: 2666
G24: VAKMANROUTE | N24: Meike Hennekam | O24: 29935
N25: Saila Kiriwenno - Dovermann | O25: 35055
N26: Inge Mulder | O26: 40975
N27: Charlotte van der Meer | O27: 36745
N28: Jama Sarwar | O28: 43035
N29: Jorine Vermeulen | O29: 24945
N30: Josine Verhagen | O30: 35335
N31: Pim de Burger | O31: 25955

Sheet report B_CategorieBoekjaar
A1: BedrijfsCode | B1: Boekjaar | C1: CategorieCode | D1: CategorieNaam | E1: CategorieGroep | F1: PrijsInkoop | G1: PrijsVerkoop | H1: hulpkolom kostprijs | I1: Hulp kolom verkoopprijs
A2: 001 | B2: 46023 | C2: 310 | D2: Zaalhuur en Catering (extern) | E2: Kosten | F2: 0 | G2: 0 | H2: =IF(report_B_CategorieBoekjaar[[#This Row],[BedrijfsCode]]="002",IF(report_B_CategorieBoekjaar[[#This Row],[Boekjaar]]=Projectbegroting!$K$1,report_B_CategorieBoekjaar[[#This Row],[CategorieCode]],0),0) -> 0 | I2: =IF(report_B_CategorieBoekjaar[[#This Row],[BedrijfsCode]]="001",IF(report_B_CategorieBoekjaar[[#This Row],[Boekjaar]]=Projectbegroting!$K$1,report_B_CategorieBoekjaar[[#This Row],[CategorieCode]],0),0) -> 310
A3: 001 | B3: 46023 | C3: 350 | D3: ICT hardware en software | E3: Kosten | F3: 0 | G3: 0 | H3: =IF(report_B_CategorieBoekjaar[[#This Row],[BedrijfsCode]]="002",IF(report_B_CategorieBoekjaar[[#This Row],[Boekjaar]]=Projectbegroting!$K$1,report_B_CategorieBoekjaar[[#This Row],[CategorieCode]],0),0) -> 0 | I3: =IF(report_B_CategorieBoekjaar[[#This Row],[BedrijfsCode]]="001",IF(report_B_CategorieBoekjaar[[#This Row],[Boekjaar]]=Projectbegroting!$K$1,report_B_CategorieBoekjaar[[#This Row],[CategorieCode]],0),0) -> 350
A4: 001 | B4: 46023 | C4: 410 | D4: Advies en Consultant | E4: Kosten | F4: 0 | G4: 0 | H4: =IF(report_B_CategorieBoekjaar[[#This Row],[BedrijfsCode]]="002",IF(report_B_CategorieBoekjaar[[#This Row],[Boekjaar]]=Projectbegroting!$K$1,report_B_CategorieBoekjaar[[#This Row],[CategorieCode]],0),0) -> 0 | I4: =IF(report_B_CategorieBoekjaar[[#This Row],[BedrijfsCode]]="001",IF(report_B_CategorieBoekjaar[[#This Row],[Boekjaar]]=Projectbegroting!$K$1,report_B_CategorieBoekjaar[[#This Row],[CategorieCode]],0),0) -> 410
A5: 001 | B5: 46023 | C5: 470 | D5: Internet en Telecommunicatie | E5: Kosten | F5: 0 | G5: 0 | H5: =IF(report_B_CategorieBoekjaar[[#This Row],[BedrijfsCode]]="002",IF(report_B_CategorieBoekjaar[[#This Row],[Boekjaar]]=Projectbegroting!$K$1,report_B_CategorieBoekjaar[[#This Row],[CategorieCode]],0),0) -> 0 | I5: =IF(report_B_CategorieBoekjaar[[#This Row],[BedrijfsCode]]="001",IF(report_B_CategorieBoekjaar[[#This Row],[Boekjaar]]=Projectbegroting!$K$1,report_B_CategorieBoekjaar[[#This Row],[CategorieCode]],0),0) -> 470
A6: 001 | B6: 46023 | C6: 490 | D6: Kantoorbenodigdheden | E6: Kosten | F6: 0 | G6: 0 | H6: =IF(report_B_CategorieBoekjaar[[#This Row],[BedrijfsCode]]="002",IF(report_B_CategorieBoekjaar[[#This Row],[Boekjaar]]=Projectbegroting!$K$1,report_B_CategorieBoekjaar[[#This Row],[CategorieCode]],0),0) -> 0 | I6: =IF(report_B_CategorieBoekjaar[[#This Row],[BedrijfsCode]]="001",IF(report_B_CategorieBoekjaar[[#This Row],[Boekjaar]]=Projectbegroting!$K$1,report_B_CategorieBoekjaar[[#This Row],[CategorieCode]],0),0) -> 490
A7: 001 | B7: 46023 | C7: 491 | D7: Lidmaatschappen, inschrijvingen en documentatie abonnementen | E7: Kosten | F7: 0 | G7: 0 | H7: =IF(report_B_CategorieBoekjaar[[#This Row],[BedrijfsCode]]="002",IF(report_B_CategorieBoekjaar[[#This Row],[Boekjaar]]=Projectbegroting!$K$1,report_B_CategorieBoekjaar[[#This Row],[CategorieCode]],0),0) -> 0 | I7: =IF(report_B_CategorieBoekjaar[[#This Row],[BedrijfsCode]]="001",IF(report_B_CategorieBoekjaar[[#This Row],[Boekjaar]]=Projectbegroting!$K$1,report_B_CategorieBoekjaar[[#This Row],[CategorieCode]],0),0) -> 491
A8: 001 | B8: 46023 | C8: 510 | D8: Verzendkosten | E8: Kosten | F8: 0 | G8: 0 | H8: =IF(report_B_CategorieBoekjaar[[#This Row],[BedrijfsCode]]="002",IF(report_B_CategorieBoekjaar[[#This Row],[Boekjaar]]=Projectbegroting!$K$1,report_B_CategorieBoekjaar[[#This Row],[CategorieCode]],0),0) -> 0 | I8: =IF(report_B_CategorieBoekjaar[[#This Row],[BedrijfsCode]]="001",IF(report_B_CategorieBoekjaar[[#This Row],[Boekjaar]]=Projectbegroting!$K$1,report_B_CategorieBoekjaar[[#This Row],[CategorieCode]],0),0) -> 510
A9: 001 | B9: 46023 | C9: 520 | D9: Drukwerk en verpakkingen | E9: Kosten | F9: 0 | G9: 0 | H9: =IF(report_B_CategorieBoekjaar[[#This Row],[BedrijfsCode]]="002",IF(report_B_CategorieBoekjaar[[#This Row],[Boekjaar]]=Projectbegroting!$K$1,report_B_CategorieBoekjaar[[#This Row],[CategorieCode]],0),0) -> 0 | I9: =IF(report_B_CategorieBoekjaar[[#This Row],[BedrijfsCode]]="001",IF(report_B_CategorieBoekjaar[[#This Row],[Boekjaar]]=Projectbegroting!$K$1,report_B_CategorieBoekjaar[[#This Row],[CategorieCode]],0),0) -> 520
A10: 001 | B10: 46023 | C10: 542 | D10: Multimedia(re)producties | E10: Kosten | F10: 0 | G10: 0 | H10: =IF(report_B_CategorieBoekjaar[[#This Row],[BedrijfsCode]]="002",IF(report_B_CategorieBoekjaar[[#This Row],[Boekjaar]]=Projectbegroting!$K$1,report_B_CategorieBoekjaar[[#This Row],[CategorieCode]],0),0) -> 0 | I10: =IF(report_B_CategorieBoekjaar[[#This Row],[BedrijfsCode]]="001",IF(report_B_CategorieBoekjaar[[#This Row],[Boekjaar]]=Projectbegroting!$K$1,report_B_CategorieBoekjaar[[#This Row],[CategorieCode]],0),0) -> 542
A11: 001 | B11: 46023 | C11: 543 | D11: ICT diensten | E11: Kosten | F11: 0 | G11: 0 | H11: =IF(report_B_CategorieBoekjaar[[#This Row],[BedrijfsCode]]="002",IF(report_B_CategorieBoekjaar[[#This Row],[Boekjaar]]=Projectbegroting!$K$1,report_B_CategorieBoekjaar[[#This Row],[CategorieCode]],0),0) -> 0 | I11: =IF(report_B_CategorieBoekjaar[[#This Row],[BedrijfsCode]]="001",IF(report_B_CategorieBoekjaar[[#This Row],[Boekjaar]]=Projectbegroting!$K$1,report_B_CategorieBoekjaar[[#This Row],[CategorieCode]],0),0) -> 543
A12: 001 | B12: 46023 | C12: 560 | D12: Examen- en itemconstructie (niet cg) | E12: Kosten | F12: 0 | G12: 0 | H12: =IF(report_B_CategorieBoekjaar[[#This Row],[BedrijfsCode]]="002",IF(report_B_CategorieBoekjaar[[#This Row],[Boekjaar]]=Projectbegroting!$K$1,report_B_CategorieBoekjaar[[#This Row],[CategorieCode]],0),0) -> 0 | I12: =IF(report_B_CategorieBoekjaar[[#This Row],[BedrijfsCode]]="001",IF(report_B_CategorieBoekjaar[[#This Row],[Boekjaar]]=Projectbegroting!$K$1,report_B_CategorieBoekjaar[[#This Row],[CategorieCode]],0),0) -> 560
A13: 001 | B13: 46023 | C13: 562 | D13: Examenbegeleiders, surveillanten | E13: Kosten | F13: 0 | G13: 0 | H13: =IF(report_B_CategorieBoekjaar[[#This Row],[BedrijfsCode]]="002",IF(report_B_CategorieBoekjaar[[#This Row],[Boekjaar]]=Projectbegroting!$K$1,report_B_CategorieBoekjaar[[#This Row],[CategorieCode]],0),0) -> 0 | I13: =IF(report_B_CategorieBoekjaar[[#This Row],[BedrijfsCode]]="001",IF(report_B_CategorieBoekjaar[[#This Row],[Boekjaar]]=Projectbegroting!$K$1,report_B_CategorieBoekjaar[[#This Row],[CategorieCode]],0),0) -> 562
... A2387: 002 | B2387: 43101 | C2387: WO-I | D2387: Wetenschappelijk onderzoeker inleen | E2387: Inhuur | F2387: 0 | G2387: 0 | H2387: =IF(report_B_CategorieBoekjaar[[#This Row],[BedrijfsCode]]="002",IF(report_B_CategorieBoekjaar[[#This Row],[Boekjaar]]=Projectbegroting!$K$1,report_B_CategorieBoekjaar[[#This Row],[CategorieCode]],0),0) -> 0 | I2387: =IF(report_B_CategorieBoekjaar[[#This Row],[BedrijfsCode]]="001",IF(report_B_CategorieBoekjaar[[#This Row],[Boekjaar]]=Projectbegroting!$K$1,report_B_CategorieBoekjaar[[#This Row],[CategorieCode]],0),0) -> 0

Sheet report B_Project
A1: BedrijfsCode | B1: ProjectCode | C1: ProjectNaam | D1: HoofdProjectCode | E1: KlantNummer | F1: KlantNaam | G1: DatumBegin | H1: DatumEinde | I1: ProjectStatus | J1: ContractId | K1: BTWCode | L1: ProjectGroep | M1: PersoneelsNummerProjectLeider | N1: NaamProjectLeider | O1: PersoneelsNummerVerkoper | P1: NaamVerkoper | Q1: PersoneelsNummerControler | R1: NaamController | S1: SorteerCode1 | T1: SorteerCode2 | U1: SorteerCode3 | V1: GrootboekAccount | W1: Kostenplaats | X1: Kostendrager | Y1: Variant | Z1: Project
A2: 002 | B2: LIBLVSALG | C2: Tijdproject Leerling in beeld volgsysteem PO | G2: 45302 | H2: 45302 | I2: In behandeling | L2: InternUur | V2: -5110-LIBLVS--LIBLVSALG | W2: 5110 | X2: LIBLVS | Z2: LIBLVSALG
A3: 002 | B3: TRAINCERTPO | C3: Tijdproject Training en Certificering PO | G3: 45302 | H3: 45302 | I3: In behandeling | L3: InternUur | V3: -5110-TRAINCERTPO--TRAINCERTPO | W3: 5110 | X3: TRAINCERTPO | Z3: TRAINCERTPO--TRAINCERTPO
A4: 002 | B4: LIBDSTALG | C4: Tijdproject Leerling in beeld doorstroomtoets | G4: 45302 | H4: 45302 | I4: In behandeling | L4: InternUur | V4: -5111-LIBDST--LIBDSTALG | W4: 5111 | X4: LIBDST | Z4: LIBDSTALG
A5: 002 | B5: CVVOCOG | C5: Tijdproject CVVO Cognitief | G5: 45302 | H5: 45302 | I5: In behandeling | L5: InternUur | V5: -5120-CVVO-COG-CVVOCOG | W5: 5120 | X5: CVVO | Y5: COG | Z5: CVVOCOG
A6: 002 | B6: CVVOALG | C6: Tijdproject CVVO Algemeen | G6: 45302 | H6: 45302 | I6: In behandeling | L6: InternUur | V6: -5120-CVVO--CVVOALG | W6: 5120 | X6: CVVO | Z6: CVVOALG
A7: 002 | B7: CVVOT0 | C7: Tijdproject CVVO Toets 0 | G7: 45302 | H7: 45302 | I7: In behandeling | L7: InternUur | V7: -5120-CVVO-T0-CVVOT0 | W7: 5120 | X7: CVVO | Y7: T0 | Z7: CVVOT0
A8: 002 | B8: CVVOT1 | C8: Tijdproject CVVO Toets 1 | G8: 45302 | H8: 45302 | I8: In behandeling | L8: InternUur | V8: -5120-CVVO-T1-CVVOT1 | W8: 5120 | X8: CVVO | Y8: T1 | Z8: CVVOT1
A9: 002 | B9: CVVOT2 | C9: Tijdproject CVVO Toets 2 | G9: 45302 | H9: 45302 | I9: In behandeling | L9: InternUur | V9: -5120-CVVO-T2-CVVOT2 | W9: 5120 | X9: CVVO | Y9: T2 | Z9: CVVOT2
A10: 002 | B10: CVVOT3 | C10: Tijdproject CVVO Toets 3 | G10: 45302 | H10: 45302 | I10: In behandeling | L10: InternUur | V10: -5120-CVVO-T3-CVVOT3 | W10: 5120 | X10: CVVO | Y10: T3 | Z10: CVVOT3
A11: 002 | B11: CVVOVSO | C11: Tijdproject CVVO VSO en PRO | G11: 45302 | H11: 45302 | I11: In behandeling | L11: InternUur | V11: -5120-CVVO-VSO-CVVOVSO | W11: 5120 | X11: CVVO | Y11: VSO | Z11: CVVOVSO
A12: 002 | B12: KLTDUI | C12: Tijdproject Kijk en luistertoets Duits | G12: 45302 | H12: 45302 | I12: In behandeling | L12: InternUur | V12: -5120-KLT-DUI-KLTDUI | W12: 5120 | X12: KLT | Y12: DUI | Z12: KLTDUI
A13: 002 | B13: KLTENG | C13: Tijdproject Kijk en luistertoets Engels | G13: 45302 | H13: 45302 | I13: In behandeling | L13: InternUur | V13: -5120-KLT-ENG-KLTENG | W13: 5120 | X13: KLT | Y13: ENG | Z13: KLTENG
A14: 002 | B14: KLTFRA | C14: Tijdproject Kijk en luistertoets Frans | G14: 45302 | H14: 45302 | I14: In behandeling | L14: InternUur | V14: -5120-KLT-FRA-KLTFRA | W14: 5120 | X14: KLT | Y14: FRA | Z14: KLTFRA
A15: 002 | B15: KLTALG | C15: Tijdproject Kijk en luistertoets algemeen | G15: 45302 | H15: 45302 | I15: In behandeling | L15: InternUur | V15: -5120-KLT--KLTALG | W15: 5120 | X15: KLT | Z15: KLTALG
A16: 002 | B16: KLTNED | C16: Tijdproject Kijk en luistertoets Nederlands | G16: 45302 | H16: 45302 | I16: In behandeling | L16: InternUur | V16: -5120-KLT-NED-KLTNED | W16: 5120 | X16: KLT | Y16: NED | Z16: KLTNED
A17: 002 | B17: KLTSPA | C17: Tijdproject Kijk en luistertoets Spaans | G17: 45302 | H17: 45302 | I17: In behandeling | L17: InternUur | V17: -5120-KLT-SPA-KLTSPA | W17: 5120 | X17: KLT | Y17: SPA | Z17: KLTSPA
A18: 002 | B18: TRAINCERTVO | C18: Tijdproject Training en Certificering VO | G18: 45302 | H18: 45302 | I18: In behandeling | L18: InternUur | V18: -5120-TRAINCERTVO--TRAINCERTVO | W18: 5120 | X18: TRAINCERTVO | Z18: TRAINCERTVO--TRAINCERTVO
A19: 002 | B19: BONDERW | C19: Tijdproject beroepsonderwijs algemeen | G19: 45302 | H19: 45302 | I19: In behandeling | L19: InternUur | V19: -5310-BONDERW--BONDERW | W19: 5310 | X19: BONDERW | Z19: BONDERW--BONDERW
A20: 002 | B20: PABOPAR | C20: Tijdproject beroepsonderwijs Pabo Particulier | G20: 45302 | H20: 45302 | I20: In behandeling | L20: InternUur | V20: -5310-BONDERW-PABOPAR-PABOPAR | W20: 5310 | X20: BONDERW | Y20: PABOPAR | Z20: PABOPAR-PABOPAR
A21: 002 | B21: TRAINCERTHO | C21: Tijdproject Training en Certificering HO | G21: 45322 | H21: 45322 | I21: In behandeling | L21: InternUur | V21: -5310-BONDERW-TRAINCERT-TRAINCERTHO | W21: 5310 | X21: BONDERW | Y21: TRAINCERT | Z21: TRAINCERTHO
A22: 002 | B22: TRAINCERTMBO | C22: Tijdproject Training en Certificering MBO | G22: 45292 | H22: 45292 | I22: In behandeling | L22: InternUur | V22: -5310-BONDERW-TRAINCERT-TRAINCERTMBO | W22: 5310 | X22: BONDERW | Y22: TRAINCERT | Z22: TRAINCERTMBO
A23: 002 | B23: TALENALG | C23: Tijdproject Talen Algemeen | G23: 45292 | H23: 45292 | I23: In behandeling | L23: InternUur | V23: -5310-TALEN--TALENALG | W23: 5310 | X23: TALEN | Z23: TALENALG
A24: 002 | B24: TRAINCERTALG | C24: Tijdproject Training en Certificering algemeen | G24: 45302 | H24: 45302 | I24: In behandeling | L24: InternUur | V24: -5310-TRAINCERTVO--TRAINCERTALG | W24: 5310 | X24: TRAINCERTVO | Z24: TRAINCERTALG
A25: 002 | B25: ZMBODEM | C25: Tijdproject Zakelijke markt Bodemenergie | G25: 45302 | H25: 45302 | I25: In behandeling | L25: InternUur | V25: -5310-ZM-BODEM-ZMBODEM | W25: 5310 | X25: ZM | Y25: BODEM | Z25: ZMBODEM
A26: 002 | B26: ZMCDD | C26: Tijdproject Zakelijke Markt CDD | G26: 45292 | H26: 45292 | I26: In behandeling | K26: NL | L26: InternUur | V26: -5310-ZM-CDD-ZMCDD | W26: 5310 | X26: ZM | Y26: CDD | Z26: ZMCDD
A27: 002 | B27: ZMISSOEPA | C27: Tijdproject Zakelijke markt ISSO Energie prestatie | G27: 45302 | H27: 45302 | I27: In behandeling | L27: InternUur | V27: -5310-ZM-ISSOEPA-ZMISSOEPA | W27: 5310 | X27: ZM | Y27: ISSOEPA | Z27: ZMISSOEPA
A28: 002 | B28: ZMMEDREK | C28: Tijdproject Zakelijke markt Medisch Rekenen | G28: 45292 | H28: 45292 | I28: In behandeling | L28: InternUur | V28: -5310-ZM-MEDREK-ZMMEDREK | W28: 5310 | X28: ZM | Y28: MEDREK | Z28: ZMMEDREK
A29: 002 | B29: ZMISSOLPA | C29: Tijdproject Zakelijke markt ISSO legionella preventie | G29: 45302 | H29: 45302 | I29: In behandeling | L29: InternUur | V29: -5310-ZM-ISSOLPA-ZMISSOLPA | W29: 5310 | X29: ZM | Y29: ISSOLPA | Z29: ZMISSOLPA
A30: 002 | B30: ZMLASSER | C30: Tijdproject Zakelijke markt Certificering PE Lassers | G30: 45302 | H30: 45302 | I30: In behandeling | L30: InternUur | V30: -5310-ZM-LASSER-ZMLASSER | W30: 5310 | X30: ZM | Y30: LASSER | Z30: ZMLASSER
A31: 002 | B31: ZMNCTV | C31: Tijdproject Zakelijke markt BAL en BAST | G31: 45302 | H31: 45302 | I31: In behandeling | L31: InternUur | V31: -5310-ZM-NCTV-ZMNCTV | W31: 5310 | X31: ZM | Y31: NCTV | Z31: ZMNCTV
A32: 002 | B32: ZMNVHP | C32: Tijdproject Zakelijke markt NVHP | G32: 45302 | H32: 45302 | I32: In behandeling | L32: InternUur | V32: -5310-ZM-NVHP-ZMNVHP | W32: 5310 | X32: ZM | Y32: NVHP | Z32: ZMNVHP
A33: 002 | B33: ZMVAKMANROUTE | C33: Tijdproject Zakelijke markt ZM Vakmanschapsroutes | G33: 45302 | H33: 45302 | I33: In behandeling | L33: InternUur | V33: -5310-ZM-VAKMANROUTE-ZMVAKMANROUTE | W33: 5310 | X33: ZM | Y33: VAKMANROUTE | Z33: ZMVAKMANROUTE
A34: 002 | B34: ZMALG | C34: Tijdproject Zakelijke markt algemeen | G34: 45302 | H34: 45302 | I34: In behandeling | L34: InternUur | V34: -5310-ZM--ZMALG | W34: 5310 | X34: ZM | Z34: ZMALG
A35: 002 | B35: 10001 | C35: 1e generatie SO / SBO BL | E35: 10021301 | F35: Cito | G35: 42737 | H35: 43465 | I35: Gereed | J35: 2000000 | K35: NL-B | L35: OVER | V35: --Uitgeverij--10001 | X35: Uitgeverij | Z35: 10001
A36: 002 | B36: 10002 | C36: 1e generatie SO / SBO RW | E36: 10021301 | F36: Cito | G36: 42737 | H36: 43465 | I36: Gereed | J36: 2000000 | K36: NL-B | L36: OVER | V36: --Uitgeverij--10002 | X36: Uitgeverij | Z36: 10002
A37: 002 | B37: 10003 | C37: 1e generatie SO / SBO SP | E37: 10021301 | F37: Cito | G37: 42737 | H37: 43465 | I37: Gereed | J37: 2000000 | K37: NL-B | L37: OVER | V37: --Uitgeverij--10003 | X37: Uitgeverij | Z37: 10003
A38: 002 | B38: 10004 | C38: 2e generatie LOVS PO BL | E38: 10021301 | F38: Cito | G38: 42737 | H38: 43465 | I38: Gereed | J38: 2000000 | K38: NL-B | L38: OVER | V38: --Uitgeverij--10004 | X38: Uitgeverij | Z38: 10004
A39: 002 | B39: 10005 | C39: 2e generatie LOVS PO RW | E39: 10021301 | F39: Cito | G39: 42737 | H39: 43465 | I39: Gereed | J39: 2000000 | K39: NL-B | L39: OVER | V39: --Uitgeverij--10005 | X39: Uitgeverij | Z39: 10005
A40: 002 | B40: 10006 | C40: 2e generatie LOVS PO SP | E40: 10021301 | F40: Cito | G40: 42737 | H40: 43465 | I40: Gereed | J40: 2000000 | K40: NL-B | L40: OVER | V40: --Uitgeverij--10006 | X40: Uitgeverij | Z40: 10006
...
